Workbook

Sheet DATA_LOADING_AND_INSPECTION
A1: customerID | B1: gender | C1: SeniorCitizen | D1: Partner | E1: Dependents | F1: tenure | G1: PhoneService | H1: MultipleLines | I1: InternetService | J1: OnlineSecurity | K1: OnlineBackup | L1: DeviceProtection | M1: TechSupport | N1: StreamingTV | O1: StreamingMovies | P1: Contract | Q1: PaperlessBilling | R1: PaymentMethod | S1: MonthlyCharges | T1: TotalCharges | U1: Churn | W1: Tenure | Z1: Monthly_Charges | AC1: Total_Charges | AF1: Contract_Type | AG1: Churn_Rate | AI1: Internet_Service | AJ1: Churn_Rate | AL1: Payment_Method | AM1: Churn_Rate | AO1: Churn | AP1: Monthly_Charges | AR1: Churn_Correlation_Heatmap
A2: 7590-VHVEG | B2: Female | C2: 0 | D2: Yes | E2: No | F2: 1 | G2: No | H2: No phone service | I2: DSL | J2: No | K2: Yes | L2: No | M2: No | N2: No | O2: No | P2: Month-to-month | Q2: Yes | R2: Electronic check | S2: 29.85 | T2: 29.85 | U2: No | AF2: Two year | AG2: =COUNTIFS($P$2:$P$7044,AF2,$U$2:$U$7044,"Yes")/COUNTIFS($P$2:$P$7044,AF2) -> 0.028318584 | AI2: No | AJ2: =COUNTIFS($I$2:$I$7044,AI2,$U$2:$U$7044,"Yes")/COUNTIFS($I$2:$I$7044,AI2) -> 0.074049803 | AL2: Credit card (automatic) | AM2: =COUNTIFS($R$2:$R$7044,AL2,$U$2:$U$7044,"Yes")/COUNTIFS($R$2:$R$7044,AL2) -> 0.15243101 | AO2: No | AP2: 18.25 | AR2: =IF(U2="Yes",1,0) -> 0
A3: 5575-GNVDE | B3: Male | C3: 0 | D3: No | E3: No | F3: 34 | G3: Yes | H3: No | I3: DSL | J3: Yes | K3: No | L3: Yes | M3: No | N3: No | O3: No | P3: One year | Q3: No | R3: Mailed check | S3: 56.95 | T3: 1889.5 | U3: No | W3: Mean | X3: 32.371149 | Z3: Mean | AA3: 64.761692 | AC3: Mean | AD3: 2283.3004 | AF3: One year | AG3: =COUNTIFS($P$2:$P$7044,AF3,$U$2:$U$7044,"Yes")/COUNTIFS($P$2:$P$7044,AF3) -> 0.11269518 | AI3: DSL | AJ3: =COUNTIFS($I$2:$I$7044,AI3,$U$2:$U$7044,"Yes")/COUNTIFS($I$2:$I$7044,AI3) -> 0.18959108 | AL3: Bank transfer (automatic) | AM3: =COUNTIFS($R$2:$R$7044,AL3,$U$2:$U$7044,"Yes")/COUNTIFS($R$2:$R$7044,AL3) -> 0.16709845 | AO3: No | AP3: 18.4 | AR3: =IF(U3="Yes",1,0) -> 0
A4: 3668-QPYBK | B4: Male | C4: 0 | D4: No | E4: No | F4: 2 | G4: Yes | H4: No | I4: DSL | J4: Yes | K4: Yes | L4: No | M4: No | N4: No | O4: No | P4: Month-to-month | Q4: Yes | R4: Mailed check | S4: 53.85 | T4: 108.15 | U4: Yes | W4: Standard Error | X4: 0.29264448 | Z4: Standard Error | AA4: 0.35854529 | AC4: Standard Error | AD4: 27.031384 | AF4: Month-to-month | AG4: =COUNTIFS($P$2:$P$7044,AF4,$U$2:$U$7044,"Yes")/COUNTIFS($P$2:$P$7044,AF4) -> 0.42709677 | AI4: Fiber optic | AJ4: =COUNTIFS($I$2:$I$7044,AI4,$U$2:$U$7044,"Yes")/COUNTIFS($I$2:$I$7044,AI4) -> 0.41892765 | AL4: Mailed check | AM4: =COUNTIFS($R$2:$R$7044,AL4,$U$2:$U$7044,"Yes")/COUNTIFS($R$2:$R$7044,AL4) -> 0.191067 | AO4: No | AP4: 18.55 | AR4: =IF(U4="Yes",1,0) -> 1
A5: 7795-CFOCW | B5: Male | C5: 0 | D5: No | E5: No | F5: 45 | G5: No | H5: No phone service | I5: DSL | J5: Yes | K5: No | L5: Yes | M5: Yes | N5: No | O5: No | P5: One year | Q5: No | R5: Bank transfer (automatic) | S5: 42.3 | T5: 1840.75 | U5: No | W5: Median | X5: 29 | Z5: Median | AA5: 70.35 | AC5: Median | AD5: 1397.475 | AL5: Electronic check | AM5: =COUNTIFS($R$2:$R$7044,AL5,$U$2:$U$7044,"Yes")/COUNTIFS($R$2:$R$7044,AL5) -> 0.45285412 | AO5: No | AP5: 18.7 | AR5: =IF(U5="Yes",1,0) -> 0
A6: 9237-HQITU | B6: Female | C6: 0 | D6: No | E6: No | F6: 2 | G6: Yes | H6: No | I6: Fiber optic | J6: No | K6: No | L6: No | M6: No | N6: No | O6: No | P6: Month-to-month | Q6: Yes | R6: Electronic check | S6: 70.7 | T6: 151.65 | U6: Yes | W6: Mode | X6: 1 | Z6: Mode | AA6: 20.05 | AC6: Mode | AD6: 20.2 | AO6: No | AP6: 18.7 | AR6: =IF(U6="Yes",1,0) -> 1
A7: 9305-CDSKC | B7: Female | C7: 0 | D7: No | E7: No | F7: 8 | G7: Yes | H7: Yes | I7: Fiber optic | J7: No | K7: No | L7: Yes | M7: No | N7: Yes | O7: Yes | P7: Month-to-month | Q7: Yes | R7: Electronic check | S7: 99.65 | T7: 820.5 | U7: Yes | W7: Standard Deviation | X7: 24.559481 | Z7: Standard Deviation | AA7: 30.090047 | AC7: Standard Deviation | AD7: 2266.7714 | AO7: No | AP7: 18.75 | AR7: =IF(U7="Yes",1,0) -> 1
A8: 1452-KIOVK | B8: Male | C8: 0 | D8: No | E8: Yes | F8: 22 | G8: Yes | H8: Yes | I8: Fiber optic | J8: No | K8: Yes | L8: No | M8: No | N8: Yes | O8: No | P8: Month-to-month | Q8: Yes | R8: Credit card (automatic) | S8: 89.1 | T8: 1949.4 | U8: No | W8: Sample Variance | X8: 603.16811 | Z8: Sample Variance | AA8: 905.41093 | AC8: Sample Variance | AD8: 5138252.4 | AO8: No | AP8: 18.8 | AR8: =IF(U8="Yes",1,0) -> 0
A9: 6713-OKOMC | B9: Female | C9: 0 | D9: No | E9: No | F9: 10 | G9: No | H9: No phone service | I9: DSL | J9: Yes | K9: No | L9: No | M9: No | N9: No | O9: No | P9: Month-to-month | Q9: No | R9: Mailed check | S9: 29.75 | T9: 301.9 | U9: No | W9: Kurtosis | X9: -1.3873716 | Z9: Kurtosis | AA9: -1.2572597 | AC9: Kurtosis | AD9: -0.23179876 | AO9: No | AP9: 18.8 | AR9: =IF(U9="Yes",1,0) -> 0
A10: 7892-POOKP | B10: Female | C10: 0 | D10: Yes | E10: No | F10: 28 | G10: Yes | H10: Yes | I10: Fiber optic | J10: No | K10: No | L10: Yes | M10: Yes | N10: Yes | O10: Yes | P10: Month-to-month | Q10: Yes | R10: Electronic check | S10: 104.8 | T10: 3046.05 | U10: Yes | W10: Skewness | X10: 0.23953975 | Z10: Skewness | AA10: -0.22052443 | AC10: Skewness | AD10: 0.9616425 | AO10: No | AP10: 18.8 | AR10: =IF(U10="Yes",1,0) -> 1
A11: 6388-TABGU | B11: Male | C11: 0 | D11: No | E11: Yes | F11: 62 | G11: Yes | H11: No | I11: DSL | J11: Yes | K11: Yes | L11: No | M11: No | N11: No | O11: No | P11: One year | Q11: No | R11: Bank transfer (automatic) | S11: 56.15 | T11: 3487.95 | U11: No | W11: Range | X11: 72 | Z11: Range | AA11: 100.5 | AC11: Range | AD11: 8666 | AO11: No | AP11: 18.8 | AR11: =IF(U11="Yes",1,0) -> 0
A12: 9763-GRSKD | B12: Male | C12: 0 | D12: Yes | E12: Yes | F12: 13 | G12: Yes | H12: No | I12: DSL | J12: Yes | K12: No | L12: No | M12: No | N12: No | O12: No | P12: Month-to-month | Q12: Yes | R12: Mailed check | S12: 49.95 | T12: 587.45 | U12: No | W12: Minimum | X12: 0 | Z12: Minimum | AA12: 18.25 | AC12: Minimum | AD12: 18.8 | AO12: No | AP12: 18.8 | AR12: =IF(U12="Yes",1,0) -> 0
A13: 7469-LKBCI | B13: Male | C13: 0 | D13: No | E13: No | F13: 16 | G13: Yes | H13: No | I13: No | J13: No internet service | K13: No internet service | L13: No internet service | M13: No internet service | N13: No internet service | O13: No internet service | P13: Two year | Q13: No | R13: Credit card (automatic) | S13: 18.95 | T13: 326.8 | U13: No | W13: Maximum | X13: 72 | Z13: Maximum | AA13: 118.75 | AC13: Maximum | AD13: 8684.8 | AO13: No | AP13: 18.8 | AR13: =IF(U13="Yes",1,0) -> 0
A14: 8091-TTVAX | B14: Male | C14: 0 | D14: Yes | E14: No | F14: 58 | G14: Yes | H14: Yes | I14: Fiber optic | J14: No | K14: No | L14: Yes | M14: No | N14: Yes | O14: Yes | P14: One year | Q14: No | R14: Credit card (automatic) | S14: 100.35 | T14: 5681.1 | U14: No | W14: Sum | X14: 227990 | Z14: Sum | AA14: 456116.6 | AC14: Sum | AD14: 16056169 | AO14: No | AP14: 18.8 | AR14: =IF(U14="Yes",1,0) -> 0
A15: 0280-XJGEX | B15: Male | C15: 0 | D15: No | E15: No | F15: 49 | G15: Yes | H15: Yes | I15: Fiber optic | J15: No | K15: Yes | L15: Yes | M15: No | N15: Yes | O15: Yes | P15: Month-to-month | Q15: Yes | R15: Bank transfer (automatic) | S15: 103.7 | T15: 5036.3 | U15: Yes | W15: Count | X15: 7043 | Z15: Count | AA15: 7043 | AC15: Count | AD15: 7032 | AO15: No | AP15: 18.85 | AR15: =IF(U15="Yes",1,0) -> 1
A16: 5129-JLPIS | B16: Male | C16: 0 | D16: No | E16: No | F16: 25 | G16: Yes | H16: No | I16: Fiber optic | J16: Yes | K16: No | L16: Yes | M16: Yes | N16: Yes | O16: Yes | P16: Month-to-month | Q16: Yes | R16: Electronic check | S16: 105.5 | T16: 2686.05 | U16: No | AO16: No | AP16: 18.85 | AR16: =IF(U16="Yes",1,0) -> 0
A17: 3655-SNQYZ | B17: Female | C17: 0 | D17: Yes | E17: Yes | F17: 69 | G17: Yes | H17: Yes | I17: Fiber optic | J17: Yes | K17: Yes | L17: Yes | M17: Yes | N17: Yes | O17: Yes | P17: Two year | Q17: No | R17: Credit card (automatic) | S17: 113.25 | T17: 7895.15 | U17: No | AO17: No | AP17: 18.85 | AR17: =IF(U17="Yes",1,0) -> 0
A18: 8191-XWSZG | B18: Female | C18: 0 | D18: No | E18: No | F18: 52 | G18: Yes | H18: No | I18: No | J18: No internet service | K18: No internet service | L18: No internet service | M18: No internet service | N18: No internet service | O18: No internet service | P18: One year | Q18: No | R18: Mailed check | S18: 20.65 | T18: 1022.95 | U18: No | AO18: No | AP18: 18.85 | AR18: =IF(U18="Yes",1,0) -> 0
A19: 9959-WOFKT | B19: Male | C19: 0 | D19: No | E19: Yes | F19: 71 | G19: Yes | H19: Yes | I19: Fiber optic | J19: Yes | K19: No | L19: Yes | M19: No | N19: Yes | O19: Yes | P19: Two year | Q19: No | R19: Bank transfer (automatic) | S19: 106.7 | T19: 7382.25 | U19: No | AO19: Yes | AP19: 18.85 | AR19: =IF(U19="Yes",1,0) -> 0
A20: 4190-MFLUW | B20: Female | C20: 0 | D20: Yes | E20: Yes | F20: 10 | G20: Yes | H20: No | I20: DSL | J20: No | K20: No | L20: Yes | M20: Yes | N20: No | O20: No | P20: Month-to-month | Q20: No | R20: Credit card (automatic) | S20: 55.2 | T20: 528.35 | U20: Yes | AO20: No | AP20: 18.9 | AR20: =IF(U20="Yes",1,0) -> 1
A21: 4183-MYFRB | B21: Female | C21: 0 | D21: No | E21: No | F21: 21 | G21: Yes | H21: No | I21: Fiber optic | J21: No | K21: Yes | L21: Yes | M21: No | N21: No | O21: Yes | P21: Month-to-month | Q21: Yes | R21: Electronic check | S21: 90.05 | T21: 1862.9 | U21: No | AO21: No | AP21: 18.9 | AR21: =IF(U21="Yes",1,0) -> 0
A22: 8779-QRDMV | B22: Male | C22: 1 | D22: No | E22: No | F22: 1 | G22: No | H22: No phone service | I22: DSL | J22: No | K22: No | L22: Yes | M22: No | N22: No | O22: Yes | P22: Month-to-month | Q22: Yes | R22: Electronic check | S22: 39.65 | T22: 39.65 | U22: Yes | AO22: No | AP22: 18.95 | AR22: =IF(U22="Yes",1,0) -> 1
A23: 1680-VDCWW | B23: Male | C23: 0 | D23: Yes | E23: No | F23: 12 | G23: Yes | H23: No | I23: No | J23: No internet service | K23: No internet service | L23: No internet service | M23: No internet service | N23: No internet service | O23: No internet service | P23: One year | Q23: No | R23: Bank transfer (automatic) | S23: 19.8 | T23: 202.25 | U23: No | AO23: No | AP23: 18.95 | AR23: =IF(U23="Yes",1,0) -> 0
A24: 1066-JKSGK | B24: Male | C24: 0 | D24: No | E24: No | F24: 1 | G24: Yes | H24: No | I24: No | J24: No internet service | K24: No internet service | L24: No internet service | M24: No internet service | N24: No internet service | O24: No internet service | P24: Month-to-month | Q24: No | R24: Mailed check | S24: 20.15 | T24: 20.15 | U24: Yes | AO24: No | AP24: 18.95 | AR24: =IF(U24="Yes",1,0) -> 1
A25: 3638-WEABW | B25: Female | C25: 0 | D25: Yes | E25: No | F25: 58 | G25: Yes | H25: Yes | I25: DSL | J25: No | K25: Yes | L25: No | M25: Yes | N25: No | O25: No | P25: Two year | Q25: Yes | R25: Credit card (automatic) | S25: 59.9 | T25: 3505.1 | U25: No | AO25: Yes | AP25: 18.95 | AR25: =IF(U25="Yes",1,0) -> 0
A26: 6322-HRPFA | B26: Male | C26: 0 | D26: Yes | E26: Yes | F26: 49 | G26: Yes | H26: No | I26: DSL | J26: Yes | K26: Yes | L26: No | M26: Yes | N26: No | O26: No | P26: Month-to-month | Q26: No | R26: Credit card (automatic) | S26: 59.6 | T26: 2970.3 | U26: No | AO26: No | AP26: 18.95 | AR26: =IF(U26="Yes",1,0) -> 0
A27: 6865-JZNKO | B27: Female | C27: 0 | D27: No | E27: No | F27: 30 | G27: Yes | H27: No | I27: DSL | J27: Yes | K27: Yes | L27: No | M27: No | N27: No | O27: No | P27: Month-to-month | Q27: Yes | R27: Bank transfer (automatic) | S27: 55.3 | T27: 1530.6 | U27: No | AO27: No | AP27: 18.95 | AR27: =IF(U27="Yes",1,0) -> 0
... A489: 3649-JPUGY | B489: Male | C489: 0 | D489: No | E489: No | F489: 72 | G489: Yes | H489: Yes | I489: DSL | J489: No | K489: Yes | L489: Yes | M489: Yes | N489: Yes | O489: Yes | P489: Two year | Q489: Yes | R489: Bank transfer (automatic) | S489: 88.6 | T489: 6201.95 | U489: No | AO489: No | AP489: 19.85 | AR489: =IF(U489="Yes",1,0) -> 0
A490: 4472-LVYGI | B490: Female | C490: 0 | D490: Yes | E490: Yes | F490: 0 | G490: No | H490: No phone service | I490: DSL | J490: Yes | K490: No | L490: Yes | M490: Yes | N490: Yes | O490: No | P490: Two year | Q490: Yes | R490: Bank transfer (automatic) | S490: 52.55 | U490: No | AO490: Yes | AP490: 19.85 | AR490: =IF(U490="Yes",1,0) -> 0
A491: 8372-JUXUI | B491: Male | C491: 0 | D491: No | E491: Yes | F491: 1 | G491: Yes | H491: Yes | I491: Fiber optic | J491: No | K491: No | L491: No | M491: No | N491: No | O491: No | P491: Month-to-month | Q491: Yes | R491: Electronic check | S491: 74.35 | T491: 74.35 | U491: Yes | AO491: No | AP491: 19.85 | AR491: =IF(U491="Yes",1,0) -> 1
A492: 3552-CTCYF | B492: Male | C492: 0 | D492: Yes | E492: Yes | F492: 63 | G492: Yes | H492: Yes | I492: Fiber optic | J492: No | K492: Yes | L492: Yes | M492: No | N492: Yes | O492: Yes | P492: Two year | Q492: Yes | R492: Bank transfer (automatic) | S492: 104.8 | T492: 6597.25 | U492: No | AO492: No | AP492: 19.85 | AR492: =IF(U492="Yes",1,0) -> 0
A493: 6778-YSNIH | B493: Female | C493: 0 | D493: No | E493: No | F493: 2 | G493: Yes | H493: No | I493: DSL | J493: No | K493: Yes | L493: No | M493: No | N493: Yes | O493: No | P493: Month-to-month | Q493: Yes | R493: Electronic check | S493: 59 | T493: 114.15 | U493: No | AO493: No | AP493: 19.85 | AR493: =IF(U493="Yes",1,0) -> 0
A494: 0388-EOPEX | B494: Female | C494: 0 | D494: Yes | E494: No | F494: 2 | G494: Yes | H494: No | I494: Fiber optic | J494: Yes | K494: No | L494: No | M494: No | N494: No | O494: No | P494: Month-to-month | Q494: Yes | R494: Electronic check | S494: 74.4 | T494: 139.4 | U494: Yes | AO494: No | AP494: 19.85 | AR494: =IF(U494="Yes",1,0) -> 1
A495: 5756-OZRIO | B495: Male | C495: 1 | D495: Yes | E495: No | F495: 61 | G495: Yes | H495: Yes | I495: DSL | J495: No | K495: Yes | L495: No | M495: No | N495: No | O495: Yes | P495: One year | Q495: No | R495: Bank transfer (automatic) | S495: 64.05 | T495: 3902.6 | U495: No | AO495: No | AP495: 19.85 | AR495: =IF(U495="Yes",1,0) -> 0
A496: 6579-JPICP | B496: Male | C496: 0 | D496: No | E496: No | F496: 1 | G496: Yes | H496: No | I496: No | J496: No internet service | K496: No internet service | L496: No internet service | M496: No internet service | N496: No internet service | O496: No internet service | P496: Month-to-month | Q496: No | R496: Mailed check | S496: 20.4 | T496: 20.4 | U496: No | AO496: No | AP496: 19.85 | AR496: =IF(U496="Yes",1,0) -> 0
A497: 8205-OTCHB | B497: Male | C497: 0 | D497: No | E497: No | F497: 22 | G497: No | H497: No phone service | I497: DSL | J497: No | K497: Yes | L497: Yes | M497: No | N497: No | O497: Yes | P497: One year | Q497: Yes | R497: Bank transfer (automatic) | S497: 43.75 | T497: 903.6 | U497: Yes | AO497: No | AP497: 19.85 | AR497: =IF(U497="Yes",1,0) -> 1
A498: 4134-BSXLX | B498: Male | C498: 0 | D498: Yes | E498: No | F498: 28 | G498: Yes | H498: No | I498: DSL | J498: Yes | K498: Yes | L498: No | M498: Yes | N498: No | O498: No | P498: Month-to-month | Q498: No | R498: Mailed check | S498: 60.9 | T498: 1785.65 | U498: No | AO498: No | AP498: 19.85 | AR498: =IF(U498="Yes",1,0) -> 0
A499: 0505-SPOOW | B499: Female | C499: 0 | D499: Yes | E499: No | F499: 70 | G499: Yes | H499: No | I499: No | J499: No internet service | K499: No internet service | L499: No internet service | M499: No internet service | N499: No internet service | O499: No internet service | P499: Two year | Q499: No | R499: Bank transfer (automatic) | S499: 19.8 | T499: 1397.65 | U499: No | AO499: No | AP499: 19.85 | AR499: =IF(U499="Yes",1,0) -> 0
A500: 6235-VDHOM | B500: Female | C500: 1 | D500: No | E500: No | F500: 5 | G500: No | H500: No phone service | I500: DSL | J500: No | K500: Yes | L500: No | M500: No | N500: No | O500: No | P500: Month-to-month | Q500: No | R500: Electronic check | S500: 28.45 | T500: 131.05 | U500: Yes | AO500: No | AP500: 19.85 | AR500: =IF(U500="Yes",1,0) -> 1
A501: 7783-YKGDV | B501: Female | C501: 0 | D501: No | E501: No | F501: 12 | G501: Yes | H501: Yes | I501: Fiber optic | J501: Yes | K501: Yes | L501: Yes | M501: No | N501: No | O501: Yes | P501: Month-to-month | Q501: Yes | R501: Bank transfer (automatic) | S501: 99.7 | T501: 1238.45 | U501: Yes | AO501: No | AP501: 19.85 | AR501: =IF(U501="Yes",1,0) -> 1
...

Sheet PIVOT_TABLE
A3: Row Labels | B3: Count of customerID | F3: Row Labels | G3: Count of customerID
A4: Month-to-month | B4: 3875 | F4: No | G4: 5174
A5: One year | B5: 1473 | F5: Yes | G5: 1869
A6: Two year | B6: 1695 | F6: Grand Total | G6: 7043
A7: Grand Total | B7: 7043

Sheet CHARTS
AL2: Correlation Heatmap | AM2: Tenure | AN2: MonthlyCharges | AO2: TotalCharges | AP2: SeniorCitizen | AQ2: ChurnFlag
AL3: Tenure | AM3: =CORREL(DATA_LOADING_AND_INSPECTION!F2:F7044,DATA_LOADING_AND_INSPECTION!F2:F7044) -> 1 | AN3: 0.24789986 | AO3: =CORREL(DATA_LOADING_AND_INSPECTION!F2:F7044,DATA_LOADING_AND_INSPECTION!T2:T7044) -> 0.82588046 | AP3: =CORREL(DATA_LOADING_AND_INSPECTION!F2:F7044,DATA_LOADING_AND_INSPECTION!C2:C7044) -> 0.016566878 | AQ3: =CORREL(DATA_LOADING_AND_INSPECTION!F2:F7044,DATA_LOADING_AND_INSPECTION!AR2:AR7044) -> -0.35222867
AL4: MonthlyCharges | AM4: 0.24789986 | AN4: =CORREL(DATA_LOADING_AND_INSPECTION!S2:S7044,DATA_LOADING_AND_INSPECTION!S2:S7044) -> 1 | AO4: =CORREL(DATA_LOADING_AND_INSPECTION!S2:S7044,DATA_LOADING_AND_INSPECTION!T2:T7044) -> 0.6510648 | AP4: =CORREL(DATA_LOADING_AND_INSPECTION!S2:S7044,DATA_LOADING_AND_INSPECTION!C2:C7044) -> 0.22017334 | AQ4: =CORREL(DATA_LOADING_AND_INSPECTION!S2:S7044,DATA_LOADING_AND_INSPECTION!AR2:AR7044) -> 0.19335642
AL5: TotalCharges | AM5: 0.82588046 | AN5: 0.6510648 | AO5: =CORREL(DATA_LOADING_AND_INSPECTION!T2:T7044,DATA_LOADING_AND_INSPECTION!T2:T7044) -> 1 | AP5: =CORREL(DATA_LOADING_AND_INSPECTION!T2:T7044,DATA_LOADING_AND_INSPECTION!C2:C7044) -> 0.10241061 | AQ5: =CORREL(DATA_LOADING_AND_INSPECTION!T2:T7044,DATA_LOADING_AND_INSPECTION!AR2:AR7044) -> -0.19948408
AL6: SeniorCitizen | AM6: 0.016566878 | AN6: 0.22017334 | AO6: 0.10241061 | AP6: =CORREL(DATA_LOADING_AND_INSPECTION!C2:C7044,DATA_LOADING_AND_INSPECTION!C2:C7044) -> 1 | AQ6: =CORREL(DATA_LOADING_AND_INSPECTION!C2:C7044,DATA_LOADING_AND_INSPECTION!AR2:AR7044) -> 0.15088933
AL7: ChurnFlag | AM7: -0.35222867 | AN7: 0.19335642 | AO7: -0.19948408 | AP7: 0.15088933 | AQ7: =CORREL(DATA_LOADING_AND_INSPECTION!AR2:AR7044,DATA_LOADING_AND_INSPECTION!AR2:AR7044) -> 1
AL10: Tenure has the strongest relationship with churn (r = -0.35) the longer a customer stays,
AL11: the less likely they are to leave while TotalCharges correlates with tenure (r = 0.83)
AL12: simply because it accumulates over time..
B17: Month-to-month customers churn at 42.7%, versus 11.3% for | K17: Fibre-optic customers churn at 41.9%, more than double DSL (19.0%) | T17: Electronic check users churn at 45.3%, | AC17: Monthly charges are widely spread, with a large low-spend cluster around $20
B18: one-year and just 2.8% for two-year contracts. | K18: and far above customers with no internet service (7.4%), | T18: nearly three times the rate of automatic bank transfer (16.7%) | AC18: (phone-only customers) and a broad hump from $65-$105
B19: Contract length is the single strongest retention lever in the data. | K19: suggesting a price or service-quality gap in the fibre product. | T19: or automatic credit card (15.2%) payers making manual payment a strong churn signal. | AC19: (bundled internet and add-on customers).
B40: 55% of the customer base is on flexible month-to-month contracts, | K40: 26.5% of ABC Communications' customers have churned historically, | T40: Churn is heavily front-loaded: customers churn at 47.4% | AC40: Churned customers have a higher median monthly bill (~$79) than retained customers (~$64),
B41: with no penalty for leaving at any time | K41: a high rate for a subscription telecom business and | T41: within their first 12 months, falling to just 6.6% after 5 years, | AC41: pointing to price sensitivity particularly among higher-paying fibre customers as a plausible churn driver
B42: structurally the highest-risk segment for churn. | K42: a clear signal that retention should be a strategic priority | T42: making the first year the critical retention window.

Sheet INSIGHTS_RECOMMENDATIONS
A1: S/N | E1: BUSINESS INSIGHTS
A3: 1 | B3: Contract flexibility is the dominant churn driver. Month-to-month customers churn at 42.7% versus 2.8% for two-year contracts — a 15x difference that dwarfs every other factor tested.
A4: 2 | B4: Churn is concentrated in the first year of the customer relationship. Customers churn at 47.4% within their first 12 months, dropping to 6.6% after 5 years — retention efforts have an outsized return if targeted at new customers.
A5: 3 | B5: Fibre-optic customers are a paradox: ABC's premium, higher-revenue service also has the highest churn rate (41.9%), suggesting a gap between what customers pay for fibre and the value/reliability they perceive.
A6: 4 | B6: Manual, non-automatic payment (especially electronic check) is a strong behavioural churn signal, with 45.3% churn versus ~15-17% for automated payment methods — far higher than can be explained by demographics alone.
A7: 5 | B7: Customers without add-on services (security, tech support, device protection) churn 2-3x more than those with them, and demographic factors — seniors, customers without partners or dependents — also show elevated churn, pointing to distinct at-risk personas.
E9: BUSINESS RISKS
A11: 1 | B11: Revenue concentration risk: With 55% of customers on month-to-month contracts and fibre customers paying the highest bills yet churning most, ABC's highest-revenue segment is also its most volatile — a disproportionate share of revenue is exposed to short-notice loss.
A12: 2 | B12: Early-life customer loss inflates acquisition cost: Because nearly half of new customers churn within the first year, ABC is effectively paying full acquisition cost for many customers who never become profitable, eroding the return on marketing and sales spend.
A13: 3 | B13: Reputational/service-quality risk in fibre: A 41.9% churn rate on the flagship fibre product, if driven by service quality or price-value perception, risks reputational damage and negative word-of-mouth that could suppress new fibre acquisition, not just retention.
E15: BUSINESS OPPORTUNITIES
A17: 1 | B17: Contract migration campaigns: Given the 15x churn gap between month-to-month and two-year contracts, even a modest shift of month-to-month customers onto annual plans (via discounts or bundled incentives) could materially reduce blended churn.
A18: 2 | B18: First-year onboarding and engagement programme: Since churn risk peaks and then decays sharply after year one, a structured 90-day/6-month/12-month check-in and engagement programme could convert a large share of at-risk new customers into long-term, low-churn customers.
A19: 3 | B19: Cross-sell of protective add-ons: Customers with security/support add-ons churn markedly less. Bundling these services (rather than selling them a la carte) into fibre and month-to-month plans could lift both revenue per customer and retention simultaneously.
E21: BUSINESS RECOMMENDATIONS
A23: 1 | B23: Incentivise longer contracts with discounts or price locks to shift month-to-month customers onto annual plans, fibre customers first.
A24: 2 | B24: Build a first-year retention journey with proactive check-ins at 30, 90, and 180 days, since that's when churn risk is highest.
A25: 3 | B25: Investigate fibre service quality and pricing to determine why it drives the highest churn despite being the premium product.
A26: 4 | B26: Encourage automatic payment adoption with small incentives to move electronic-check customers off manual billing.
A27: 5 | B27: Bundle security, tech support, and device protection into core plans instead of selling them separately, to boost both stickiness and revenue.
